Workbook
Name _3’端修饰: 修饰名称!$B$2:$B$49
Name _5’端修饰: 修饰名称!$A$2:$A$49
Name 两端修饰: 修饰名称!$C$2:$C$50

Sheet 引物合成订购表
B1: 全国免费电话： | C1: 生工生物工程（上海）股份有限公司 引物合成订购表 免费热线电话：400-821-0268；800-820-1016 网址：www.sangon.com
J2: 订购日期： | K2: =NOW() -> 45352.849
A4: *订购人姓名 | B4: 1 | D4: 上海合成部：synth@sangon.com 电话：021-57072173/72/71 | I4: 成都合成部：cdsynth@sangon.com 电话：028-64259944
A5: *订购人手机 | D5: 北京合成部：beijing@sangon.com 电话：010-81767585/86 | I5: 青岛合成部：qdsynth@sangon.com 电话：0532-68012226
A6: *订购人E-MAIL： | B6: 1 | D6: 广州合成部：gz_synth@sangon.com 电话：020-38452026 | I6: 南京合成部：njsynth@sangon.com 电话：025-85383702
A7: *负责人/法人： | B7: 1 | D7: 武汉合成部：whsynth@sangon.com 电话：027-65522298 | I7: 郑州合成部：zzsynth@sangon.com 电话：0371-61652655
A8: *固定电话： | D8: 订单要求： 1. 此表格同时适用于线上和线下（E-mail）订单提交使用； 2. 鼠标移至单元格右上角红色小三角查看批注提示。按批注提示，进一步查看“帮助”工作表获取对选项更详细的解释和说明； 3. 由于订单提交后由系统自动处理，请务必在订单提交前仔细核对所填写的信息，此表格中*号的字段表示必填项，线下（E-mail）订单需完整填写表头部分信息，线上提交无需填写； 4.（E-mail）订单接收到邮件回复后将不能再更改或取消，如未收到邮件回复请电话确认，为了避免重复下订单，请您不要重复发送； 5. 我们提供以OD量或nmoles为合成量提交订单，两者任选其一填写即可，且都只能填写数字不能有其它字符，如两者均有填写默认以OD量为准； 6. 此表格提交的引物条数没有上限，如引物条数超过ID编号可下拉继续填写； 7. 中间修饰的填写方法请结合表格中的“帮助”和“填写示例”工作表，其他内容详见各列项中的填写说明，您也可以在“填写示例”工作表中查看到各列项的填写方式。
A9: *订购人单位： | B9: 1
A10: *发票抬头： | B10: 1
A11: *付款方式：
A12: 随货开票：
A13: *收货地址：
A14: *备注：
A15: *是否双休日发货
A16: *是否部分先发货 | D16: 总碱基数 | E16: =SUM(D18:D113) -> 184
A17: ID（此处无需填写） | B17: Primer名称 | C17: 序列（5' to 3'） | D17: 碱基数 | E17: 分装管数 | F17: 提供总量（OD） | G17: 纯化方法 | H17: nmoles | I17: 5'端修饰 | J17: 3'端修饰 | K17: 5'端和3’端双标记修饰
A18: 01 | B18: WK-CTB-F | C18: ggtatcgaaggtaggcatatgATGATTAAACTGAAATTTGGCGTTT | D18: 46 | E18: 1 | F18: 2 | G18: HAP
A19: 02 | B19: WK-CTB-R | C19: agactgcaggtcgacaagcttTTAATGATGATGGTGATGATGTTTCG | D19: 47 | E19: 1 | F19: 2 | G19: HAP
A20: 03 | B20: WK-纯肽-F | C20: ggtatcgaaggtaggcatatgGCAGGAGATATTGAAGCGCTTAA | D20: 44 | E20: 1 | F20: 2 | G20: HAP
A21: 04 | B21: WK-纯肽-R | C21: agactgcaggtcgacaagcttTTAATGATGATGGTGATGATGTTTCG | D21: 47 | E21: 1 | F21: 2 | G21: HAP
A22: 05
A23: 06
A24: 07
A25: 08 | D25: {=LEN(C25)-SUM((LEN(C25)-LEN(SUBSTITUTE(C25,修饰名称!$E$2:$E$93,修饰名称!$F$2:$F$93))))} -> 0
A26: 09 | D26: {=LEN(C26)-SUM((LEN(C26)-LEN(SUBSTITUTE(C26,修饰名称!$E$2:$E$93,修饰名称!$F$2:$F$93))))} -> 0
A27: 10 | D27: {=LEN(C27)-SUM((LEN(C27)-LEN(SUBSTITUTE(C27,修饰名称!$E$2:$E$93,修饰名称!$F$2:$F$93))))} -> 0
A28: 11 | D28: {=LEN(C28)-SUM((LEN(C28)-LEN(SUBSTITUTE(C28,修饰名称!$E$2:$E$93,修饰名称!$F$2:$F$93))))} -> 0
A29: 12 | D29: {=LEN(C29)-SUM((LEN(C29)-LEN(SUBSTITUTE(C29,修饰名称!$E$2:$E$93,修饰名称!$F$2:$F$93))))} -> 0
A30: 13 | D30: {=LEN(C30)-SUM((LEN(C30)-LEN(SUBSTITUTE(C30,修饰名称!$E$2:$E$93,修饰名称!$F$2:$F$93))))} -> 0
A31: 14 | D31: {=LEN(C31)-SUM((LEN(C31)-LEN(SUBSTITUTE(C31,修饰名称!$E$2:$E$93,修饰名称!$F$2:$F$93))))} -> 0
A32: 15 | D32: {=LEN(C32)-SUM((LEN(C32)-LEN(SUBSTITUTE(C32,修饰名称!$E$2:$E$93,修饰名称!$F$2:$F$93))))} -> 0
A33: 16 | D33: {=LEN(C33)-SUM((LEN(C33)-LEN(SUBSTITUTE(C33,修饰名称!$E$2:$E$93,修饰名称!$F$2:$F$93))))} -> 0
A34: 17 | D34: {=LEN(C34)-SUM((LEN(C34)-LEN(SUBSTITUTE(C34,修饰名称!$E$2:$E$93,修饰名称!$F$2:$F$93))))} -> 0
A35: 18 | D35: {=LEN(C35)-SUM((LEN(C35)-LEN(SUBSTITUTE(C35,修饰名称!$E$2:$E$93,修饰名称!$F$2:$F$93))))} -> 0
A36: 19 | D36: {=LEN(C36)-SUM((LEN(C36)-LEN(SUBSTITUTE(C36,修饰名称!$E$2:$E$93,修饰名称!$F$2:$F$93))))} -> 0
... A317: 300 | D317: {=LEN(C317)-SUM((LEN(C317)-LEN(SUBSTITUTE(C317,修饰名称!$E$2:$E$93,修饰名称!$F$2:$F$93))))} -> 0

Sheet 修饰名称
A1: 5’端修饰 | B1: 3’端修饰 | C1: 两端修饰 | D1: 中间修饰 | E1: 中间修饰代码 | F1: 中间修饰碱基
A2: 5`6-FAM | B2: 3`6-FAM | C2: 5`6-FAM，3`BHQ1 | D2: 1-Me-dA | E2: /i1-MedA/ | F2: A
A3: 5`Acrydite | B3: 3`Acrydite | C3: 5`6-FAM，3`BHQ2 | D3: 2-Aminopurine | E3: /i2-Amp/ | F3: A
A4: 5`Alexa Fluor 350 | B4: 3`Alexa Fluor 350 | C4: 5`6-FAM，3`Dabcyl | D4: 5-Aza-2`-deoxycytidine | E4: /i5-AzadC/ | F4: C
A5: 5`Alexa Fluor 405 | B5: 3`Alexa Fluor 405 | C5: 5`6-FAM，3`DBQ1 | D5: 5-Bromo dU | E5: /i5Br-dU/ | F5: U
A6: 5`Alexa Fluor 430 | B6: 3`Alexa Fluor 430 | C6: 5`6-FAM，3`Eclipse | D6: 5F-dU | E6: /i5F-dU/ | F6: U
A7: 5`Alexa Fluor 488 | B7: 3`Alexa Fluor 488 | C7: 5`6-FAM，3`MGB | D7: 5-Hydroxmethyl dC | E7: /55HydMe-dC/ | F7: C
A8: 5`Alexa Fluor 532 | B8: 3`Alexa Fluor 532 | C8: 5`6-FAM，3`TAMRA-N | D8: 5-Methyl dC | E8: /i5MedC/ | F8: C
A9: 5`Alexa Fluor 555 | B9: 3`Alexa Fluor 555 | C9: 5`CY3，3`BHQ2 | D9: 5-Nitroindole | E9: /i5NitInd/
A10: 5`Alexa Fluor 568 | B10: 3`Alexa Fluor 568 | C10: 5`CY3，3`Dabcyl-N | D10: 8-OXO-dG | E10: /i8oxodG/ | F10: G
A11: 5`Alexa Fluor 594 | B11: 3`Alexa Fluor 594 | C11: 5`CY3，3`MGB | D11: Azobenzene | E11: /iAbz/
A12: 5`Alexa Fluor 647 | B12: 3`Alexa Fluor 647 | C12: 5`CY5，3`BHQ2 | D12: C12 Spacer | E12: /iSpC12/
A13: 5`Alexa Fluor 680 | B13: 3`Alexa Fluor 680 | C13: 5`CY5，3`BHQ-3 | D13: C3 Spacer | E13: /iSpC3/
A14: 5`AMCA | B14: 3`AMCA | C14: 5`CY5，3`Dabcyl | D14: C6 Spacer | E14: /iSp6/
A15: 5`Atto 425 | B15: 3`AquaPhluor 593 | C15: 5`CY5，3`MGB | D15: deoxyInosine (dI) | E15: /ideoxyI/ | F15: I
A16: 5`ATTO 590 | B16: 3`Atto 425 | C16: 5`CY5.5，3`BHQ2 | D16: deoxyUridine (dU) | E16: /ideoxyU/ | F16: U
A17: 5`Azide(N3) | B17: 3`ATTO 590 | C17: 5`HEX，3`BHQ1 | D17: dSpacer | E17: /idSp/
A18: 5`BBQ650 | B18: 3`Azide(N3) | C18: 5`HEX，3`BHQ2 | D18: Int 6-FAM-dT | E18: /i6FAMdT/ | F18: T
A19: 5`BHQ1 | B19: 3`BBQ650 | C19: 5`HEX，3`Dabcyl | D19: Int Acrydite dT | E19: /iAcryditedT/ | F19: T
A20: 5`BHQ2 | B20: 3`BHQ1 | C20: 5`HEX，3`DBQ1 | D20: Int Alexa Fluor 350 dT | E20: /iAF350dT/ | F20: T
A21: 5`Biotin | B21: 3`BHQ2 | C21: 5`HEX，3`Eclipse | D21: Int Alexa Fluor 405 dT | E21: /iAF405dT/ | F21: T
A22: 5`Biotin-TEG | B22: 3`BHQ-3 | C22: 5`HEX，3`MGB | D22: Int Alexa Fluor 430 dT | E22: /iAF430dT/ | F22: T
A23: 5`BODIPY FL | B23: 3`Biotin | C23: 5`HEX，3`TAMRA | D23: Int Alexa Fluor 488-dT | E23: /iAF488dT/ | F23: T
A24: 5`C3 Spacer | B24: 3`Biotin-TEG | C24: 5`JOE，3`BHQ1 | D24: Int Alexa Fluor 532 dT | E24: /iAF532dT/ | F24: T
A25: 5`CHCH(Hexyne) | B25: 3`BODIPY FL | C25: 5`JOE，3`BHQ2 | D25: Int Alexa Fluor 555 dT | E25: /iAF555dT/ | F25: T
A26: 5`CHO | B26: 3`C3 Spacer | C26: 5`JOE，3`Dabcyl-N | D26: Int Alexa Fluor 568 dT | E26: /iAF568dT/ | F26: T
A27: 5`Cholesteryl | B27: 3`C6 Spacer | C27: 5`JOE，3`MGB | D27: Int Alexa Fluor 594 dT | E27: /iAF594dT/ | F27: T
A28: 5`Cholesteryl-TEG | B28: 3`CHCH | C28: 5`JOE，3`TAMRA-N | D28: Int Alexa Fluor 647 dT | E28: /iAF647dT/ | F28: T
A29: 5`COOH | B29: 3`Cholesteryl | C29: 5`Quasar 670，3`BHQ2 | D29: Int Alexa Fluor 680 dT | E29: /iAF680dT/ | F29: T
... A37: 5`DBCO-TEG | B37: 3`DBCO | C37: 5`TAMRA，3`MGB | D37: Int CHCH-dT | E37: /iCHCHdT/ | F37: T
A38: 5`Desthio Biotin | B38: 3`ddC | C38: 5`TET，3`BHQ1 | D38: Int Cy3 | E38: /iCy3/
A39: 5`Desthio Biotin-TEG | B39: 3`Desthio Biotin-TEG | C39: 5`TET，3`BHQ2 | D39: Int Cy3-dT | E39: /iCy3dT/ | F39: T
A40: 5`Dig | B40: 3`-dG-Q | C40: 5`TET，3`Dabcyl | D40: Int Cy5 | E40: /iCy5/
A41: 5`Dithiol | B41: 3`Dig | C41: 5`TET，3`MGB | D41: Int Cy5-dT | E41: /iCy5dT/ | F41: T
A42: 5`Dual Biotin | B42: 3`Dithiol | C42: 5`TET，3`TAMRA | D42: Int Cy5(Hydrophilic) dT | E42: /iCy5HdT/ | F42: T
A43: 5`Eclipse | B43: 3`-dT-Q | C43: 5`Texas Red，3`BHQ2 | D43: Int CY5.5 dT | E43: /iCY5.5dT/ | F43: T
A44: 5`Ferrocene | B44: 3`Eclipse | C44: 5`Texas Red，3`Dabcyl | D44: Int CY7 dT | E44: /iCY7dT/ | F44: T
A45: 5`HEX | B45: 3`Ferrocene | C45: 5`Texas Red，3`MGB | D45: Int Dabcyl-dT | E45: /iDabcyldT/ | F45: T
A46: 5`HS-SH C6 | B46: 3`Ferrocene-N | C46: 5`VIC，3`BHQ1 | D46: Int DBCO dT | E46: /iDBCOdT/ | F46: T
A47: 5`IR 650 | B47: 3`HEX | C47: 5`VIC，3`BHQ2 | D47: Int Desthio Biotin dT | E47: /iDesBiodT/ | F47: T
...

Sheet 帮助
A1: 纯化方式选择 | N1: 引物修饰列表 | T1: 简并碱基
A2: 维度 | E2: 纯化方式 | N2: 5'修饰 | O2: 3’修饰 | P2: 5'端和3’端双标记修饰 | Q2: 中间修饰 | R2: 中间修饰代码 | S2: 中间修饰碱基 | T2: 简并碱基代码
E3: HAP | F3: PAGE | G3: ULTRAPAGE | H3: HPLC | I3: HPLC_CE (IVD) | J3: IE-HPLC | K3: 2X HPLC | L3: PAGE+HPLC | N3: 修饰引物仅适用于HPLC、HPLC_CE、IE-HPLC、2X HPLC和PAGE+HPLC纯化 | T3: 不适合IE-HPLC和2X HPLC纯化
A4: 按片段长度 | N4: 5`6-FAM | O4: 3`6-FAM | P4: 5`6-FAM，3`BHQ1 | Q4: 1-Me-dA | R4: /i1-MedA/ | S4: A | T4: B=C/G/T
A5: 短片段（~10 mer) | H5: √ | N5: 5`Acrydite | O5: 3`Acrydite | P5: 5`6-FAM，3`BHQ2 | Q5: 2-Aminopurine | R5: /i2-Amp/ | S5: A | T5: D=A/G/T
A6: 中片段（11~59 mer) | E6: √ | F6: √ | G6: √ | H6: √ | I6: √ | J6: √ | K6: √ | L6: √ | N6: 5`Alexa Fluor 350 | O6: 3`Alexa Fluor 350 | P6: 5`6-FAM，3`Dabcyl | Q6: 5-Aza-2`-deoxycytidine | R6: /i5-AzadC/ | S6: C | T6: H=A/C/T
A7: 长片段（60~130 mer) | G7: √ | H7: √ | J7: √ | K7: √ | L7: √ | N7: 5`Alexa Fluor 405 | O7: 3`Alexa Fluor 405 | P7: 5`6-FAM，3`DBQ1（双淬灭） | Q7: 5-Bromo dU | R7: /i5Br-dU/ | S7: U | T7: I=Universal Base
A8: 超长片段（131 mer~)* | K8: √ | L8: √ | N8: 5`Alexa Fluor 430 | O8: 3`Alexa Fluor 430 | P8: 5`6-FAM，3`Eclipse | Q8: 5F-dU | R8: /i5F-dU/ | S8: U | T8: K=G/T
A9: 按应用 | N9: 5`Alexa Fluor 488 | O9: 3`Alexa Fluor 488 | P9: 5`6-FAM，3`MGB | Q9: 5-Hydroxmethyl dC | R9: /55HydMe-dC/ | S9: C | T9: M=A/C
A10: 普通PCR/多重PCR/逆转录PCR（RT-PCR） | E10: √ | F10: √ | G10: √ | H10: √ | I10: √ | J10: √ | K10: √ | L10: √ | N10: 5`Alexa Fluor 532 | O10: 3`Alexa Fluor 532 | P10: 5`6-FAM，3`TAMRA-N | Q10: 5-Methyl dC | R10: /i5MedC/ | S10: C | T10: N=A/C/G/T
A11: 荧光定量PCR（qPCR）/数字PCR（dPCR） | E11: √ | F11: √ | G11: √ | H11: √ | I11: √ | J11: √ | K11: √ | L11: √ | N11: 5`Alexa Fluor 555 | O11: 3`Alexa Fluor 555 | P11: 5`CY3，3`BHQ2 | Q11: 5-Nitroindole | R11: /i5NitInd/ | T11: R=A/G
A12: 一代测序（Sanger） | E12: √ | F12: √ | G12: √ | H12: √ | I12: √ | J12: √ | K12: √ | L12: √ | N12: 5`Alexa Fluor 568 | O12: 3`Alexa Fluor 568 | P12: 5`CY3，3`Dabcyl-N | Q12: 8-OXO-dG | R12: /i8oxodG/ | S12: G | T12: S=C/G
A13: 高通量测序（NGS） | E13: √ | F13: √ | G13: √ | H13: √ | I13: √ | J13: √ | K13: √ | L13: √ | N13: 5`Alexa Fluor 594 | O13: 3`Alexa Fluor 594 | P13: 5`CY3，3`MGB | Q13: Azobenzene | R13: /iAbz/ | T13: V=A/C/G
A14: 全基因合成 | E14: √ | F14: √ | G14: √ | H14: √ | I14: √ | J14: √ | K14: √ | L14: √ | N14: 5`Alexa Fluor 647 | O14: 3`Alexa Fluor 647 | P14: 5`CY5，3`BHQ2 | Q14: C12 Spacer | R14: /iSpC12/ | T14: W=A/T
A15: 亚克隆/点突变 | F15: √ | G15: √ | H15: √ | I15: √ | J15: √ | K15: √ | L15: √ | N15: 5`Alexa Fluor 680 | O15: 3`Alexa Fluor 680 | P15: 5`CY5，3`BHQ-3 | Q15: C3 Spacer | R15: /iSpC3/ | T15: Y=C/T
A16: 基因构建/RNA干扰 | F16: √ | G16: √ | H16: √ | I16: √ | J16: √ | K16: √ | L16: √ | N16: 5`AMCA | O16: 3`AMCA | P16: 5`CY5，3`Dabcyl | Q16: C6 Spacer | R16: /iSp6/
A17: PCR产物用于克隆表达研究或基因重组等 | G17: √ | H17: √ | I17: √ | J17: √ | K17: √ | L17: √ | N17: 5`Atto 425 | O17: 3`AquaPhluor 593 | P17: 5`CY5，3`DBQ2（双淬灭） | Q17: deoxyInosine (dI) | R17: /ideoxyI/ | S17: I
A18: 反义核酸 | H18: √ | I18: √ | J18: √ | K18: √ | L18: √ | N18: 5`ATTO 590 | O18: 3`Atto 425 | P18: 5`CY5，3`MGB | Q18: deoxyUridine (dU) | R18: /ideoxyU/ | S18: U
A19: 修饰或标记引物 | H19: √ | I19: √ | J19: √ | K19: √ | L19: √ | N19: 5`Azide(N3) | O19: 3`ATTO 590 | P19: 5`CY5.5，3`BHQ2 | Q19: dSpacer | R19: /idSp/
A20: 化学及物理应用 | H20: √ | I20: √ | J20: √ | K20: √ | L20: √ | N20: 5`BBQ650 | O20: 3`Azide(N3) | P20: 5`HEX，3`BHQ1 | Q20: Int 6-FAM-dT | R20: /i6FAMdT/ | S20: T
A21: 体外诊断应用 | I21: √ | N21: 5`BHQ1 | O21: 3`BBQ650 | P21: 5`HEX，3`BHQ2 | Q21: Int Acrydite dT | R21: /iAcryditedT/ | S21: T
A22: 备注： *由于超长片段合成难度较大，我们无法保证其成功率及纯度等，如需合成，请提前与技术支持沟通咨询； | N22: 5`BHQ2 | O22: 3`BHQ1 | P22: 5`HEX，3`Dabcyl | Q22: Int Alexa Fluor 350 dT | R22: /iAF350dT/ | S22: T
N23: 5`Biotin | O23: 3`BHQ2 | P23: 5`HEX，3`DBQ1（双淬灭） | Q23: Int Alexa Fluor 405 dT | R23: /iAF405dT/ | S23: T
N24: 5`Biotin-TEG | O24: 3`BHQ-3 | P24: 5`HEX，3`Eclipse | Q24: Int Alexa Fluor 430 dT | R24: /iAF430dT/ | S24: T
N25: 5`BODIPY FL | O25: 3`Biotin | P25: 5`HEX，3`MGB | Q25: Int Alexa Fluor 488-dT | R25: /iAF488dT/ | S25: T
A26: 附加服务项 | N26: 5`C3 Spacer | O26: 3`Biotin-TEG | P26: 5`HEX，3`TAMRA | Q26: Int Alexa Fluor 532 dT | R26: /iAF532dT/ | S26: T
A27: 额外QC检测服务 | N27: 5`CHCH(Hexyne) | O27: 3`BODIPY FL | P27: 5`JOE，3`BHQ1 | Q27: Int Alexa Fluor 555 dT | R27: /iAF555dT/ | S27: T
A28: 项目名 | E28: 代码 | G28: 单位 | H28: 简要说明 | K28: 适用范围 | N28: 5`CHO | O28: 3`C3 Spacer | P28: 5`JOE，3`BHQ2 | Q28: Int Alexa Fluor 568 dT | R28: /iAF568dT/ | S28: T
A29: HPLC纯度 | E29: HPLC | G29: % | H29: 引物的纯度是否满足对应标准 | K29: 全系 | N29: 5`Cholesteryl | O29: 3`C6 Spacer | P29: 5`JOE，3`Dabcyl-N | Q29: Int Alexa Fluor 594 dT | R29: /iAF594dT/ | S29: T
A30: CE纯度 | E30: CE | G30: % | N30: 5`Cholesteryl-TEG | O30: 3`CHCH | P30: 5`JOE，3`MGB | Q30: Int Alexa Fluor 647 dT | R30: /iAF647dT/ | S30: T
A31: PAGE纯度 | E31: PAGE | G31: % | N31: 5`COOH | O31: 3`Cholesteryl | P31: 5`JOE，3`TAMRA-N | Q31: Int Alexa Fluor 680 dT | R31: /iAF680dT/ | S31: T
A32: 荧光激发/发射波长 | E32: Ex/Em | G32: nm | H32: 荧光修饰引物的激发/发射光谱波长是否正常 | K32: 荧光修饰引物、qPCR探针 | N32: 5`Cy3 | O32: 3`Cholesteryl-TEG | P32: 5`Quasar 670，3`BHQ2 | Q32: Int Atto 425 dT | R32: /iAtto425dT/ | S32: T
A33: 荧光值酶切增量 | E33: FLU | G33: P/F | H33: TaqMan探针、分子信标等常规双标记引物的荧光、淬灭基团功能是否正常 | K33: 双标记qPCR探针、分子信标 | N33: 5`Cy5 | O33: 3`Cy3 | P33: 5`ROX，3`BHQ2 | Q33: Int Azide-dT | R33: /iAzidedT/ | S33: T
A34: 人源污染检测 | E34: HSC | G34: P/F | H34: 引物是否污染人源基因组DNA | N34: 5`Cy5(Hydrophilic) | O34: 3`Cy5 | P34: 5`ROX，3`Dabcyl | Q34: Int BBQ650 dT | R34: /iBBQ650dT/ | S34: T
A35: 无模板对照检测 | E35: NTC | G35: P/F | H35: qPCR引物探针在无模板体系中是否会体现出不正常的扩增信号 | N35: 5`CY5.5 | O35: 3`Cy5(Hydrophilic) | P35: 5`ROX，3`DBQ2（双淬灭） | Q35: Int BHQ1 dT | R35: /iBHQ1dT/ | S35: T
A36: 交叉污染率 | E36: CCR | G36: % | H36: 不同引物之间的交叉污染概率 | K36: NGS引物 | N36: 5`Cy7 | O36: 3`CY5.5 | P36: 5`ROX，3`Eclipse | Q36: Int BHQ2 dT | R36: /iBHQ2dT/ | S36: T
N37: 5`Dabcyl | O37: 3`Cy7 | P37: 5`ROX，3`MGB | Q37: Int Biotin dT | R37: /iBiodT/ | S37: T
N38: 5`DBCO | O38: 3`Dabcyl | P38: 5`TAMRA，3`BHQ2 | Q38: Int BODIPY FL dT | R38: /iBODIPYFLdT/ | S38: T
N39: 5`DBCO-TEG | O39: 3`DBCO | P39: 5`TAMRA，3`Dabcyl | Q39: Int CHCH-dT | R39: /iCHCHdT/ | S39: T
N40: 5`Desthio Biotin | O40: 3`ddC | P40: 5`TAMRA，3`Eclipse | Q40: Int Cy3 | R40: /iCy3/
...

Sheet 填写示例
A1: OD量下单填写示例：
A2: ID（此处无需填写） | B2: Primer名称 | C2: 序列（5' to 3'） | D2: 碱基数 | E2: 分装管数 | F2: 提供总量（OD） | G2: 纯化方法 | H2: nmoles | I2: 5'端修饰 | J2: 3'端修饰 | K2: 5'端和3’端双标记修饰
A3: 01 | B3: P1 | C3: AGCTAGCTAGCTAGCTAGCT | D3: {=LEN(C3)-SUM((LEN(C3)-LEN(SUBSTITUTE(C3,修饰名称!$E$2:$E$93,修饰名称!$F$2:$F$93))))} -> 20 | E3: 1 | F3: 2 | G3: HAP
A4: 02 | B4: P2 | C4: GCATGCATGCATGCATGCAT | D4: {=LEN(C4)-SUM((LEN(C4)-LEN(SUBSTITUTE(C4,修饰名称!$E$2:$E$93,修饰名称!$F$2:$F$93))))} -> 20 | E4: 1 | F4: 5 | G4: ULTRAPAGE
A5: 03 | B5: P3 | C5: CAGTCAGTCAGTCAGTCAGT | D5: {=LEN(C5)-SUM((LEN(C5)-LEN(SUBSTITUTE(C5,修饰名称!$E$2:$E$93,修饰名称!$F$2:$F$93))))} -> 20 | E5: 1 | F5: 10 | G5: HPLC
A6: 04 | B6: P4 | C6: TCAGTCAGTCAGTCAGTCAG | D6: {=LEN(C6)-SUM((LEN(C6)-LEN(SUBSTITUTE(C6,修饰名称!$E$2:$E$93,修饰名称!$F$2:$F$93))))} -> 20 | E6: 1 | F6: 2 | G6: IE-HPLC
A7: 05 | B7: P5 | C7: ATCGATCGATCGATCGATCG | D7: {=LEN(C7)-SUM((LEN(C7)-LEN(SUBSTITUTE(C7,修饰名称!$E$2:$E$93,修饰名称!$F$2:$F$93))))} -> 20 | E7: 1 | F7: 5 | G7: 2X HPLC
A9: nmoles下单填写示例：
A10: ID（此处无需填写） | B10: Primer名称 | C10: 序列（5' to 3'） | D10: 碱基数 | E10: 分装管数 | F10: 提供总量（OD） | G10: 纯化方法 | H10: nmoles | I10: 5'端修饰 | J10: 3'端修饰 | K10: 5'端和3’端双标记修饰
A11: 01 | B11: P1 | C11: AGCTAGCTAGCTAGCTAGCT | D11: {=LEN(C11)-SUM((LEN(C11)-LEN(SUBSTITUTE(C11,修饰名称!$E$2:$E$93,修饰名称!$F$2:$F$93))))} -> 20 | E11: 1 | G11: HAP | H11: 10
A12: 02 | B12: P2 | C12: GCATGCATGCATGCATGCAT | D12: {=LEN(C12)-SUM((LEN(C12)-LEN(SUBSTITUTE(C12,修饰名称!$E$2:$E$93,修饰名称!$F$2:$F$93))))} -> 20 | E12: 1 | G12: ULTRAPAGE | H12: 25
A13: 03 | B13: P3 | C13: CAGTCAGTCAGTCAGTCAGT | D13: {=LEN(C13)-SUM((LEN(C13)-LEN(SUBSTITUTE(C13,修饰名称!$E$2:$E$93,修饰名称!$F$2:$F$93))))} -> 20 | E13: 1 | G13: HPLC | H13: 50
A14: 04 | B14: P4 | C14: TCAGTCAGTCAGTCAGTCAG | D14: {=LEN(C14)-SUM((LEN(C14)-LEN(SUBSTITUTE(C14,修饰名称!$E$2:$E$93,修饰名称!$F$2:$F$93))))} -> 20 | E14: 1 | G14: IE-HPLC | H14: 10
A15: 05 | B15: P5 | C15: ATCGATCGATCGATCGATCG | D15: {=LEN(C15)-SUM((LEN(C15)-LEN(SUBSTITUTE(C15,修饰名称!$E$2:$E$93,修饰名称!$F$2:$F$93))))} -> 20 | E15: 1 | G15: 2X HPLC | H15: 25
A17: 5'端修饰填写示例：
A18: ID（此处无需填写） | B18: Primer名称 | C18: 序列（5' to 3'） | D18: 碱基数 | E18: 分装管数 | F18: 提供总量（OD） | G18: 纯化方法 | H18: nmoles | I18: 5'端修饰 | J18: 3'端修饰 | K18: 5'端和3’端双标记修饰
A19: 01 | B19: P1 | C19: AGCTAGCTAGCTAGCTAGCT | D19: {=LEN(C19)-SUM((LEN(C19)-LEN(SUBSTITUTE(C19,修饰名称!$E$2:$E$93,修饰名称!$F$2:$F$93))))} -> 20 | E19: 1 | F19: 2 | G19: HPLC | I19: 5`6-FAM
A20: 02 | B20: P2 | C20: GCATGCATGCATGCATGCAT | D20: {=LEN(C20)-SUM((LEN(C20)-LEN(SUBSTITUTE(C20,修饰名称!$E$2:$E$93,修饰名称!$F$2:$F$93))))} -> 20 | E20: 1 | F20: 5 | G20: HPLC | I20: 5`Biotin
A21: 03 | B21: P3 | C21: CAGTCAGTCAGTCAGTCAGT | D21: {=LEN(C21)-SUM((LEN(C21)-LEN(SUBSTITUTE(C21,修饰名称!$E$2:$E$93,修饰名称!$F$2:$F$93))))} -> 20 | E21: 1 | F21: 10 | G21: HPLC | I21: 5`NH2 C6
A23: 3'端修饰填写示例：
A24: ID（此处无需填写） | B24: Primer名称 | C24: 序列（5' to 3'） | D24: 碱基数 | E24: 分装管数 | F24: 提供总量（OD） | G24: 纯化方法 | H24: nmoles | I24: 5'端修饰 | J24: 3'端修饰 | K24: 5'端和3’端双标记修饰
A25: 01 | B25: P1 | C25: AGCTAGCTAGCTAGCTAGCT | D25: {=LEN(C25)-SUM((LEN(C25)-LEN(SUBSTITUTE(C25,修饰名称!$E$2:$E$93,修饰名称!$F$2:$F$93))))} -> 20 | E25: 1 | F25: 2 | G25: HPLC | J25: 3`P
A26: 02 | B26: P2 | C26: GCATGCATGCATGCATGCAT | D26: {=LEN(C26)-SUM((LEN(C26)-LEN(SUBSTITUTE(C26,修饰名称!$E$2:$E$93,修饰名称!$F$2:$F$93))))} -> 20 | E26: 1 | F26: 5 | G26: HPLC | J26: 3`Dig
A27: 03 | B27: P3 | C27: CAGTCAGTCAGTCAGTCAGT | D27: {=LEN(C27)-SUM((LEN(C27)-LEN(SUBSTITUTE(C27,修饰名称!$E$2:$E$93,修饰名称!$F$2:$F$93))))} -> 20 | E27: 1 | F27: 10 | G27: HPLC | J27: 3`SH C6
A29: 5'端和3’端双标记修饰填写示例：
A30: ID（此处无需填写） | B30: Primer名称 | C30: 序列（5' to 3'） | D30: 碱基数 | E30: 分装管数 | F30: 提供总量（OD） | G30: 纯化方法 | H30: nmoles | I30: 5'端修饰 | J30: 3'端修饰 | K30: 5'端和3’端双标记修饰
A31: 01 | B31: P1 | C31: AGCTAGCTAGCTAGCTAGCT | D31: {=LEN(C31)-SUM((LEN(C31)-LEN(SUBSTITUTE(C31,修饰名称!$E$2:$E$93,修饰名称!$F$2:$F$93))))} -> 20 | E31: 1 | F31: 2 | G31: HPLC | K31: 5`6-FAM，3`BHQ1
A32: 02 | B32: P2 | C32: GCATGCATGCATGCATGCAT | D32: {=LEN(C32)-SUM((LEN(C32)-LEN(SUBSTITUTE(C32,修饰名称!$E$2:$E$93,修饰名称!$F$2:$F$93))))} -> 20 | E32: 1 | F32: 5 | G32: HPLC | K32: 5`HEX，3`BHQ1
A33: 03 | B33: P3 | C33: CAGTCAGTCAGTCAGTCAGT | D33: {=LEN(C33)-SUM((LEN(C33)-LEN(SUBSTITUTE(C33,修饰名称!$E$2:$E$93,修饰名称!$F$2:$F$93))))} -> 20 | E33: 1 | F33: 10 | G33: HPLC | K33: 5`CY5，3`BHQ2
A35: 中间修饰填写示例：
A36: ID（此处无需填写） | B36: Primer名称 | C36: 序列（5' to 3'） | D36: 碱基数 | E36: 分装管数 | F36: 提供总量（OD） | G36: 纯化方法 | H36: nmoles | I36: 5'端修饰 | J36: 3'端修饰 | K36: 5'端和3’端双标记修饰
A37: 01 | B37: P1 | C37: AGCTAGCAGC/iSp18/TAGCTAGCT | D37: {=LEN(C37)-SUM((LEN(C37)-LEN(SUBSTITUTE(C37,修饰名称!$E$2:$E$93,修饰名称!$F$2:$F$93))))} -> 19 | E37: 1 | F37: 2 | G37: HPLC
A38: 02 | B38: P2 | C38: GCA/i6FAMdT/GCATGCATGCA/iBHQ1dT/GCAT | D38: {=LEN(C38)-SUM((LEN(C38)-LEN(SUBSTITUTE(C38,修饰名称!$E$2:$E$93,修饰名称!$F$2:$F$93))))} -> 20 | E38: 1 | F38: 5 | G38: HPLC
A39: 03 | B39: P3 | C39: /i2OMeA/*A*GTCAGT/i5MedC/AGT/i5MedC/AGTCA*G*/i2OMeC/ | D39: {=LEN(C39)-SUM((LEN(C39)-LEN(SUBSTITUTE(C39,修饰名称!$E$2:$E$93,修饰名称!$F$2:$F$93))))} -> 34 | E39: 1 | F39: 10 | G39: HPLC
A41: *以上为示例，仅供参考。
